<?xml version="1.0"?>
<sdf version="1.6">
  <model name="simple_door">
    <link name="frame_left">
      <pose>-0.025 0.5 1.0 0 0 0</pose>
      <visual name="v_fl"><geometry><box><size>0.05 0.05 2.0</size></box></geometry></visual>
      <collision name="c_fl"><geometry><box><size>0.05 0.05 2.0</size></box></geometry></collision>
      <static>true</static>
    </link>
    <link name="frame_right">
      <pose>-0.025 -0.5 1.0 0 0 0</pose>
      <visual name="v_fr"><geometry><box><size>0.05 0.05 2.0</size></box></geometry></visual>
      <collision name="c_fr"><geometry><box><size>0.05 0.05 2.0</size></box></geometry></collision>
      <static>true</static>
    </link>
    <link name="frame_top">
      <pose>-0.025 0 2.025 0 0 0</pose>
      <visual name="v_ft"><geometry><box><size>0.05 1.0 0.05</size></box></geometry></visual>
      <collision name="c_ft"><geometry><box><size>0.05 1.0 0.05</size></box></geometry></collision>
      <static>true</static>
    </link>
    
    <link name="door_panel">
      <pose>-0.025 0 1.0 0 0 0</pose>
      <inertial>
        <mass>10</mass>
        <inertia><ixx>1</ixx><iyy>1</iyy><izz>1</izz></inertia>
      </inertial>
      <visual name="v_d"><geometry><box><size>0.04 0.9 2.0</size></box></geometry></visual>
      <collision name="c_d"><geometry><box><size>0.04 0.9 2.0</size></box></geometry></collision>
    </link>
    
    <joint name="hinge" type="revolute">
      <parent>frame_left</parent>
      <child>door_panel</child>
      <axis>
        <xyz>0 0 1</xyz>
        <limit>
          <lower>0</lower>
          <upper>1.57</upper>
        </limit>
      </axis>
    </joint>
  </model>
</sdf>
